<?xml version="1.0" encoding="utf-8"?>
<!-- =================================================================================== -->
<!-- |    This document was autogenerated by xacro from ../ex00/robot.urdf             | -->
<!-- |    EDITING THIS FILE BY HAND IS NOT RECOMMENDED                                 | -->
<!-- =================================================================================== -->

<robot name="robot" xmlns:xacro="http://www.ros.org/wiki/xacro">
  <xacro:include filename="$(find robot_diff_drive)/urdf/robot.gazebo.xacro"/>

  <material name="gray">
    <color rgba="0.5 0.5 0.5 1"/>
  </material>

  <material name="black">
    <color rgba="0 0 0 1"/>
  </material>

  <link name="base_link">
    <visual>
      <geometry>
        <cylinder length="2.0" radius="1.05"/>
      </geometry>
      <material name="gray"/>
    </visual>
    <collision>
      <geometry>
        <cylinder length="2.0" radius="1.05"/>
      </geometry>
    </collision>
    <inertial>
      <mass value="20"/>
      <inertia ixx="12.1792" ixy="0.0" ixz="0.0" iyy="12.1792" iyz="0.0" izz="11.025"/>
    </inertial>
  </link>

  <link name="right_wheel">
    <visual>
      <geometry>
        <cylinder length="0.25" radius="0.25"/>
      </geometry>
      <origin rpy="1.57075 1.57075 0"/>
      <material name="black"/>
    </visual>
    <collision>
      <geometry>
        <cylinder length="0.25" radius="0.25"/>
      </geometry>
      <origin rpy="1.57075 1.57075 0"/>
    </collision>
    <inertial>
      <mu1 value="2.0"/>
      <mu2 value="1.0"/>
      <kp value="10000000.0" />
      <kd value="1.0" />
      <mass value="4"/>
      <inertia ixx="0.0833" ixy="0.0" ixz="0.0" iyy="0.0833" iyz="0.0" izz="0.125"/>
    </inertial>
  </link>

  <joint name="right_wheel_to_base_link" type="continuous">
    <parent link="base_link"/>
    <child link="right_wheel"/>
    <axis xyz="0 1 0"/>
    <origin xyz="0.4 0.5 -1.2"/>
  </joint>

  <transmission name="right_wheel_trans">
    <type>transmission_interface/SimpleTransmission</type>
    <actuator name="right_wheel_motor">
      <mechanicalReduction>1</mechanicalReduction>
    </actuator>
    <joint name="right_wheel_to_base_link">
      <hardwareInterface>hardware_interface/VelocityJointInterface</hardwareInterface>
    </joint>
  </transmission>

  <gazebo reference="right_wheel">
    <mu1 value="2.0"/>
    <mu2 value="1.0"/>
    <kp value="10000000.0" />
    <kd value="1.0" />
    <material>Gazebo/Grey</material>
  </gazebo>

  <link name="left_wheel">
    <visual>
      <geometry>
        <cylinder length="0.25" radius="0.25"/>
      </geometry>
      <origin rpy="1.57075 1.57075 0"/>
      <material name="black"/>
    </visual>
    <collision>
      <geometry>
        <cylinder length="0.25" radius="0.25"/>
      </geometry>
      <origin rpy="1.57075 1.57075 0"/>
    </collision>
    <inertial>
      <mu1 value="2.0"/>
      <mu2 value="1.0"/>
      <kp value="10000000.0" />
      <kd value="1.0" />
      <mass value="4"/>
      <inertia ixx="0.0833" ixy="0.0" ixz="0.0" iyy="0.0833" iyz="0.0" izz="0.125"/>
    </inertial>
  </link>

  <joint name="left_wheel_to_base_link" type="continuous">
    <parent link="base_link"/>
    <child link="left_wheel"/>
    <axis xyz="0 1 0"/>
    <origin xyz="0.4 -0.5 -1.2"/>
  </joint>

  <transmission name="left_wheel_trans">
    <type>transmission_interface/SimpleTransmission</type>
    <actuator name="left_wheel_motor">
      <mechanicalReduction>1</mechanicalReduction>
    </actuator>
    <joint name="left_wheel_to_base_link">
      <hardwareInterface>hardware_interface/VelocityJointInterface</hardwareInterface>
    </joint>
  </transmission>

  <gazebo reference="left_wheel">
    <mu1 value="2.0"/>
    <mu2 value="1.0"/>
    <kp value="10000000.0" />
    <kd value="1.0" />
    <material>Gazebo/Grey</material>
  </gazebo>

  <link name="custer">
    <visual>
      <geometry>
        <sphere radius="0.25"/>
      </geometry>
      <origin rpy="0 0 0"/>
      <material name="black"/>
    </visual>
    <collision>
      <geometry>
        <sphere radius="0.25"/>
      </geometry>
    </collision>
    <inertial>
      <mu1 value="0.01"/>
      <mu2 value="0.01"/>
      <kp value="10000000.0" />
      <kd value="1.0" />
      <mass value="5"/>
      <inertia ixx="0.125" ixy="0.0" ixz="0.0" iyy="0.125" iyz="0.0" izz="0.125"/>
    </inertial>
  </link>

  <joint name="custer_to_base_link" type="fixed">
    <parent link="base_link"/>
    <child link="custer"/>
    <origin xyz="-0.4 0.0 -1.2"/>
    <limit effort="1000" velocity="10"/>
  </joint>

  <transmission name="custer_to_base_link_trans">
    <type>transmission_interface/SimpleTransmission</type>
    <actuator name="custer_to_base_link_motor">
      <mechanicalReduction>1</mechanicalReduction>
    </actuator>
    <joint name="custer_to_base_link">
      <hardwareInterface>hardware_interface/PositionJointInterface</hardwareInterface>
    </joint>
  </transmission>

  <gazebo reference="custer">
    <mu1 value="0.01"/>
    <mu2 value="0.01"/>
    <kp value="10000000.0" />
    <kd value="1.0" />
    <material>Gazebo/Grey</material>
  </gazebo>

  <!-- Hokuyo LiDAR -->
  <link name="hokuyo_link">
    <visual>
      <geometry>
        <mesh filename="package://robot_diff_drive/meshes/hokuyo.dae"/>
      </geometry>
    </visual>
    <collision>
      <geometry>
        <box size="0.1 0.1 0.1"/>
      </geometry>
    </collision>
    <inertial>
      <mass value="1e-5"/>
      <inertia ixx="1e-6" ixy="0.0" ixz="0.0" iyy="1e-6" iyz="0.0" izz="1e-6"/>
    </inertial>
  </link>

  <joint name="hokuyo_joint" type="fixed">
    <origin xyz="1.1 0 -0.9"/>
    <parent link="base_link"/>
    <child link="hokuyo_link"/>
  </joint>

  <gazebo reference="hokuyo_link">
    <sensor type="gpu_ray" name="head_hokuyo_sensor">
      <pose>0 0 0 0 0 0</pose>
      <visualize>false</visualize>
      <update_rate>40</update_rate>
      <ray>
        <scan>
          <horizontal>
            <samples>720</samples>
            <resolution>1</resolution>
            <min_angle>-1.570796</min_angle>
            <max_angle>1.570796</max_angle>
          </horizontal>
        </scan>
        <range>
          <min>0.1</min>
          <max>30.0</max>
          <resolution>0.01</resolution>
        </range>
        <noise>
          <mean>0.0</mean>
          <stddev>0.01</stddev>
        </noise>
      </ray>
      <plugin name="gazebo_ros_head_hokuyo_controller" filename="libgazebo_ros_gpu_laser.so">
        <topicName>/laser/scan</topicName>
        <frameName>hokuyo_link</frameName>
      </plugin>
    </sensor>
  </gazebo>

  <!-- Gazebo plugin for ROS Control -->
  <gazebo>
    <plugin name="gazebo_ros_control" filename="libgazebo_ros_control.so">
      <robotNamespace>/</robotNamespace>
    </plugin>
  </gazebo>
</robot>

