<?xml version="1.0" encoding="utf-8"?>
<!-- =================================================================================== -->
<!-- |    This document was autogenerated by xacro from ../ex00/robot.urdf             | -->
<!-- |    EDITING THIS FILE BY HAND IS NOT RECOMMENDED                                 | -->
<!-- =================================================================================== -->
<robot name="robot">
  <material name="gray">
    <color rgba="0.5 0.5 0.5 1"/>
  </material>
  <material name="black">
    <color rgba="0 0 0 1"/>
  </material>
  <link name="base_link">
    <visual>
      <geometry>
        <cylinder length="2.0" radius="1.05"/>
      </geometry>
      <material name="gray"/>
    </visual>
    <collision>
      <geometry>
        <cylinder length="2.0" radius="1.05"/>
      </geometry>
    </collision>
    <inertial>
      <mass value="20"/>
      <inertia ixx="15.05" ixy="0.0" ixz="0.0" iyy="15.05" iyz="0.0" izz="11.05"/>
    </inertial>
  </link>
  <link name="right_wheel">
    <visual>
      <geometry>
        <cylinder length="0.25" radius="0.25"/>
      </geometry>
      <origin rpy="1.57075 1.57075 0"/>
      <material name="black"/>
    </visual>
    <collision>
      <geometry>
        <cylinder length="0.25" radius="0.25"/>
      </geometry>
      <origin rpy="1.57075 1.57075 0"/>
    </collision>
    <inertial>
      <mu value="0.5"/>
      <mass value="4"/>
      <inertia ixx="0.52" ixy="0.0" ixz="0.0" iyy="0.52" iyz="0.0" izz="0.125"/>
    </inertial>
  </link>
  <joint name="right_wheel_to_base_link" type="continuous">
    <parent link="base_link"/>
    <child link="right_wheel"/>
    <axis xyz="0 1 0"/>
    <origin xyz="0.4 0.5 -1.2"/>
  </joint>
  <link name="left_wheel">
    <visual>
      <geometry>
        <cylinder length="0.25" radius="0.25"/>
      </geometry>
      <origin rpy="1.57075 1.57075 0"/>
      <material name="black"/>
    </visual>
    <collision>
      <geometry>
        <cylinder length="0.25" radius="0.25"/>
      </geometry>
    </collision>
    <inertial>
      <mu value="0.5"/>
      <mass value="4"/>
      <inertia ixx="0.52" ixy="0.0" ixz="0.0" iyy="0.52" iyz="0.0" izz="0.125"/>
    </inertial>
  </link>
  <joint name="left_wheel_to_base_link" type="continuous">
    <parent link="base_link"/>
    <child link="left_wheel"/>
    <axis xyz="0 1 0"/>
    <origin xyz="0.4 -0.5 -1.2"/>
  </joint>
  <link name="custer_x">
    <visual>
      <geometry>
        <sphere radius="0.25"/>
      </geometry>
      <origin rpy="0 0 0"/>
      <material name="black"/>
    </visual>
    <collision>
      <geometry>
        <sphere radius="0.25"/>
      </geometry>
    </collision>
    <inertial>
      <mu value="0.1"/>
      <mass value="5"/>
      <inertia ixx="0.125" ixy="0.0" ixz="0.0" iyy="0.125" iyz="0.0" izz="0.125"/>
    </inertial>
  </link>
  <joint name="custer_x_to_base_link" type="continuous">
    <parent link="base_link"/>
    <child link="custer_x"/>
    <axis xyz="1 0 0"/>
    <origin xyz="-0.5 0.0 -1.2"/>
  </joint>
  <link name="custer_y">
    <visual>
      <geometry>
        <sphere radius="0.25"/>
      </geometry>
      <origin rpy="0 0 0"/>
      <material name="black"/>
    </visual>
    <collision>
      <geometry>
        <sphere radius="0.25"/>
      </geometry>
    </collision>
    <inertial>
      <mu value="0.1"/>
      <mass value="5"/>
      <inertia ixx="0.125" ixy="0.0" ixz="0.0" iyy="0.125" iyz="0.0" izz="0.125"/>
    </inertial>
  </link>
  <joint name="custer_y_to_base_link" type="continuous">
    <parent link="base_link"/>
    <child link="custer_y"/>
    <axis xyz="0 1 0"/>
    <origin xyz="-0.5 0.0 -1.2"/>
  </joint>
  <link name="custer_z">
    <visual>
      <geometry>
        <sphere radius="0.25"/>
      </geometry>
      <origin rpy="0 0 0"/>
      <material name="black"/>
    </visual>
    <collision>
      <geometry>
        <sphere radius="0.25"/>
      </geometry>
    </collision>
    <inertial>
      <mu value="0.1"/>
      <mass value="5"/>
      <inertia ixx="0.125" ixy="0.0" ixz="0.0" iyy="0.125" iyz="0.0" izz="0.125"/>
    </inertial>
  </link>
  <joint name="custer_z_to_base_link" type="continuous">
    <parent link="base_link"/>
    <child link="custer_z"/>
    <axis xyz="0 0 1"/>
    <origin xyz="-0.5 0.0 -1.2"/>
  </joint>
</robot>

