<?xml version="1.0" ?>
<robot name="robot_diff_drive" xmlns:xacro="http://ros.org/wiki/xacro">
  <xacro:include filename="$(find robot_diff_drive)/urdf/common_properties.xacro"/>
  <xacro:include filename="$(find robot_diff_drive)/urdf/robot_diff_drive.gazebo.xacro"/>

  <link name="base_footprint"/>

  <link name="base_link">
    <visual>
      <origin xyz="0.0 0.0 0.05" rpy="0 0 0"/>
      <geometry>
        <cylinder length="0.1" radius="0.05"/>
      </geometry>
      <material name="gray"/>
    </visual>

    <collision>
      <origin xyz="0.0 0.0 0.05" rpy="0 0 0"/>
      <geometry>
        <cylinder length="0.1" radius="0.05"/>
      </geometry>
    </collision>

    <inertial>
      <origin xyz="0 0 0" rpy="0 0 0"/>
      <mass value="8.2573504e-01"/>
      <inertia ixx="2.2124416e-03" ixy="-1.2294101e-05" ixz="3.4938785e-05"
               iyy="2.1193702e-03" iyz="-5.0120904e-06"
               izz="2.0064271e-03" />
    </inertial>
  </link>

  <joint name="base_joint" type="fixed">
      <parent link="base_footprint"/>
      <child link="base_link"/>
      <origin xyz="0.0 0.0 0.020" rpy="0 0 0"/>
  </joint>

  <link name="wheel_left_link">
    <visual>
      <origin xyz="0 0 0" rpy="0 0 0"/>
      <geometry>
        <cylinder length="0.018" radius="0.020"/>
      </geometry>
      <material name="black"/>
    </visual>

    <collision>
      <origin xyz="0 0 0" rpy="0 0 0"/>
      <geometry>
        <cylinder length="0.018" radius="0.020"/>
      </geometry>
    </collision>

    <inertial>
      <origin xyz="0 0 0" />
      <mass value="2.8498940e-02" />
      <inertia ixx="1.1175580e-05" ixy="-4.2369783e-11" ixz="-5.9381719e-09"
               iyy="1.1192413e-05" iyz="-1.4400107e-11"
               izz="2.0712558e-05" />
      </inertial>
  </link>

  <joint name="wheel_left_joint" type="continuous">
    <parent link="base_link"/>
    <child link="wheel_left_link"/>
    <origin xyz="0.0 0.06 0.0" rpy="-1.57 0 0"/>
    <axis xyz="0 0 1"/>
  </joint>

  <link name="wheel_right_link">
    <visual>
      <origin xyz="0 0 0" rpy="0 0 0"/>
      <geometry>
        <cylinder length="0.018" radius="0.020"/>
      </geometry>
      <material name="black"/>
    </visual>

    <collision>
      <origin xyz="0 0 0" rpy="0 0 0"/>
      <geometry>
        <cylinder length="0.018" radius="0.020"/>
      </geometry>
    </collision>

    <inertial>
      <origin xyz="0 0 0" />
      <mass value="2.8498940e-02" />
      <inertia ixx="1.1175580e-05" ixy="-4.2369783e-11" ixz="-5.9381719e-09"
               iyy="1.1192413e-05" iyz="-1.4400107e-11"
               izz="2.0712558e-05" />
      </inertial>
  </link>

  <joint name="wheel_right_joint" type="continuous">
    <parent link="base_link"/>
    <child link="wheel_right_link"/>
    <origin xyz="0.0 -0.06 0.0" rpy="-1.57 0 0"/>
    <axis xyz="0 0 1"/>
  </joint>

  <link name="caster_back_link">
    <visual>
      <origin xyz="0 0 0" rpy="0 0 0"/>
      <geometry>
        <sphere radius="0.02"/>
      </geometry>
    </visual>

    <collision>
      <origin xyz="0 0 0" rpy="0 0 0"/>
      <geometry>
        <sphere radius="0.02"/>
      </geometry>
    </collision>

    <inertial>
      <origin xyz="0 0 0" />
      <mass value="0.005" />
      <inertia ixx="0.001" ixy="0.0" ixz="0.0"
               iyy="0.001" iyz="0.0"
               izz="0.001" />
    </inertial>
  </link>

  <joint name="caster_back_joint" type="fixed">
    <parent link="base_link"/>
    <child link="caster_back_link"/>
    <origin xyz="-0.028 0 0.0" rpy="0 0 0"/>
  </joint>

  <!-- Hokuyo LiDAR -->
  <link name="hokuyo_link">
    <visual>
      <geometry>
        <mesh filename="package://robot_diff_drive/meshes/hokuyo.dae"/>
      </geometry>
    </visual>

    <collision>
      <geometry>
        <box size="0.1 0.1 0.1"/>
      </geometry>
    </collision>

    <inertial>
      <mass value="1e-5"/>
      <inertia ixx="1e-6" ixy="0.0" ixz="0.0" iyy="1e-6" iyz="0.0" izz="1e-6"/>
    </inertial>
  </link>

  <joint name="hokuyo_joint" type="fixed">
    <origin xyz="0.0 0.0 0.09"/>
    <parent link="base_link"/>
    <child link="hokuyo_link"/>
  </joint>

</robot>
