<?xml version="1.0" encoding="utf-8"?>
<!-- =================================================================================== -->
<!-- |    This document was autogenerated by xacro from ../ex00/robot.urdf             | -->
<!-- |    EDITING THIS FILE BY HAND IS NOT RECOMMENDED                                 | -->
<!-- =================================================================================== -->

<robot name="robot" xmlns:xacro="http://www.ros.org/wiki/xacro">
  <xacro:include filename="$(find robot_diff_drive)/urdf/robot.gazebo.xacro"/>

  <material name="gray">
    <color rgba="0.5 0.5 0.5 1"/>
  </material>

  <material name="black">
    <color rgba="0 0 0 1"/>
  </material>

  <link name="base_link">
    <visual>
      <geometry>
        <cylinder length="0.2" radius="0.105"/>
      </geometry>
      <material name="gray"/>
    </visual>
    <collision>
      <geometry>
        <cylinder length="0.2" radius="0.105"/>
      </geometry>
    </collision>
    <inertial>
      <mass value="2"/>
      <inertia ixx="1.21792" ixy="0.0" ixz="0.0" iyy="1.21792" iyz="0.0" izz="1.1025"/>
    </inertial>
  </link>

  <link name="right_wheel">
    <visual>
      <geometry>
        <cylinder length="0.025" radius="0.025"/>
      </geometry>
      <origin rpy="1.57075 1.57075 0"/>
      <material name="black"/>
    </visual>
    <collision>
      <geometry>
        <cylinder length="0.025" radius="0.025"/>
      </geometry>
      <origin rpy="1.57075 1.57075 0"/>
    </collision>
    <inertial>
      <mu1 value="2.0"/>
      <mu2 value="1.0"/>
      <kp value="10000000.0" />
      <kd value="1.0" />
      <mass value="0.4"/>
      <inertia ixx="0.00833" ixy="0.0" ixz="0.0" iyy="0.00833" iyz="0.0" izz="0.0125"/>
    </inertial>
  </link>

  <joint name="right_wheel_to_base_link" type="continuous">
    <parent link="base_link"/>
    <child link="right_wheel"/>
    <axis xyz="0 1 0"/>
    <origin xyz="0.04 0.05 -0.12"/>
  </joint>

  <transmission name="right_wheel_trans">
    <type>transmission_interface/SimpleTransmission</type>
    <actuator name="right_wheel_motor">
      <mechanicalReduction>1</mechanicalReduction>
    </actuator>
    <joint name="right_wheel_to_base_link">
      <hardwareInterface>hardware_interface/VelocityJointInterface</hardwareInterface>
    </joint>
  </transmission>

  <gazebo reference="right_wheel">
    <mu1 value="2.0"/>
    <mu2 value="1.0"/>
    <kp value="10000000.0" />
    <kd value="1.0" />
    <material>Gazebo/Grey</material>
  </gazebo>

  <link name="left_wheel">
    <visual>
      <geometry>
        <cylinder length="0.025" radius="0.025"/>
      </geometry>
      <origin rpy="1.57075 1.57075 0"/>
      <material name="black"/>
    </visual>
    <collision>
      <geometry>
        <cylinder length="0.025" radius="0.025"/>
      </geometry>
      <origin rpy="1.57075 1.57075 0"/>
    </collision>
    <inertial>
      <mu1 value="2.0"/>
      <mu2 value="1.0"/>
      <kp value="10000000.0" />
      <kd value="1.0" />
      <mass value="0.4"/>
      <inertia ixx="0.00833" ixy="0.0" ixz="0.0" iyy="0.00833" iyz="0.0" izz="0.0125"/>
    </inertial>
  </link>

  <joint name="left_wheel_to_base_link" type="continuous">
    <parent link="base_link"/>
    <child link="left_wheel"/>
    <axis xyz="0 1 0"/>
    <origin xyz="0.04 -0.05 -0.12"/>
  </joint>

  <transmission name="left_wheel_trans">
    <type>transmission_interface/SimpleTransmission</type>
    <actuator name="left_wheel_motor">
      <mechanicalReduction>1</mechanicalReduction>
    </actuator>
    <joint name="left_wheel_to_base_link">
      <hardwareInterface>hardware_interface/VelocityJointInterface</hardwareInterface>
    </joint>
  </transmission>

  <gazebo reference="left_wheel">
    <mu1 value="2.0"/>
    <mu2 value="1.0"/>
    <kp value="10000000.0" />
    <kd value="1.0" />
    <material>Gazebo/Grey</material>
  </gazebo>

  <link name="custer">
    <visual>
      <geometry>
        <sphere radius="0.025"/>
      </geometry>
      <origin rpy="0 0 0"/>
      <material name="black"/>
    </visual>
    <collision>
      <geometry>
        <sphere radius="0.025"/>
      </geometry>
    </collision>
    <inertial>
      <mu1 value="0.01"/>
      <mu2 value="0.01"/>
      <kp value="10000000.0" />
      <kd value="1.0" />
      <mass value="0.5"/>
      <inertia ixx="0.0125" ixy="0.0" ixz="0.0" iyy="0.0125" iyz="0.0" izz="0.0125"/>
    </inertial>
  </link>

  <joint name="custer_to_base_link" type="fixed">
    <parent link="base_link"/>
    <child link="custer"/>
    <origin xyz="-0.04 0.0 -0.12"/>
    <limit effort="1000" velocity="10"/>
  </joint>

  <transmission name="custer_to_base_link_trans">
    <type>transmission_interface/SimpleTransmission</type>
    <actuator name="custer_to_base_link_motor">
      <mechanicalReduction>1</mechanicalReduction>
    </actuator>
    <joint name="custer_to_base_link">
      <hardwareInterface>hardware_interface/PositionJointInterface</hardwareInterface>
    </joint>
  </transmission>

  <gazebo reference="custer">
    <mu1 value="0.01"/>
    <mu2 value="0.01"/>
    <kp value="10000000.0" />
    <kd value="1.0" />
    <material>Gazebo/Grey</material>
  </gazebo>

  <!-- Hokuyo LiDAR -->
  <link name="hokuyo_link">
    <visual>
      <geometry>
        <mesh filename="package://robot_diff_drive/meshes/hokuyo.dae"/>
      </geometry>
    </visual>
    <collision>
      <geometry>
        <box size="0.1 0.1 0.1"/>
      </geometry>
    </collision>
    <inertial>
      <mass value="1e-5"/>
      <inertia ixx="1e-6" ixy="0.0" ixz="0.0" iyy="1e-6" iyz="0.0" izz="1e-6"/>
    </inertial>
  </link>

  <joint name="hokuyo_joint" type="fixed">
    <origin xyz="0.11 0.0 0.09"/>
    <parent link="base_link"/>
    <child link="hokuyo_link"/>
  </joint>

  <gazebo reference="hokuyo_link">
    <sensor type="gpu_ray" name="head_hokuyo_sensor">
      <pose>0 0 0 0 0 0</pose>
      <visualize>false</visualize>
      <update_rate>40</update_rate>
      <ray>
        <scan>
          <horizontal>
            <samples>720</samples>
            <resolution>1</resolution>
            <min_angle>-1.570796</min_angle>
            <max_angle>1.570796</max_angle>
          </horizontal>
        </scan>
        <range>
          <min>0.1</min>
          <max>30.0</max>
          <resolution>0.01</resolution>
        </range>
        <noise>
          <mean>0.0</mean>
          <stddev>0.01</stddev>
        </noise>
      </ray>
      <plugin name="gazebo_ros_head_hokuyo_controller" filename="libgazebo_ros_gpu_laser.so">
        <topicName>/laser/scan</topicName>
        <frameName>hokuyo_link</frameName>
      </plugin>
    </sensor>
  </gazebo>

  <!-- <link name="kinect_link">
    <visual>
      <geometry>
        <box size="0.03 0.03 0.03"/>
      </geometry>
      <material name="black"/>
    </visual>
    <collision>
      <geometry>
        <box size="0.03 0.03 0.03"/>
      </geometry>
    </collision>
    <inertial>
      <mass value="1e-5"/>
      <inertia ixx="1e-6" ixy="0.0" ixz="0.0" iyy="1e-6" iyz="0.0" izz="1e-6"/>
    </inertial>
  </link>

  <joint name="kinect_joint" type="fixed">
    <origin xyz="0.11 0.0 -0.05"/>
    <parent link="base_link"/>
    <child link="kinect_link"/>
  </joint>

  <link name="kinect_optical_link">
    <collision>
      <geometry>
        <box size="0.03 0.03 0.03"/>
      </geometry>
    </collision>
    <inertial>
      <mass value="1e-5"/>
      <inertia ixx="1e-6" ixy="0.0" ixz="0.0" iyy="1e-6" iyz="0.0" izz="1e-6"/>
    </inertial>
  </link>

  <joint name="kinect_optical_joint" type="fixed">
    <origin rpy="-1.570796 0 -1.570796"/>
    <parent link="kinect_link"/>
    <child link="kinect_optical_link"/>
  </joint>

  <gazebo reference="kinect_link">
    <sensor type="depth" name="kinect">
      <update_rate>20</update_rate>
      <camera>
        <horizontal_fov>1.547198</horizontal_fov>
        <image>
          <width>640</width>
          <height>480</height>
          <format>R8G8B8</format>
        </image>
        <clip>
          <near>0.05</near>
          <far>30.0</far>
        </clip>
      </camera>
      <plugin name="kinect_link_controller" filename="libgazebo_ros_openni_kinect.so">
        <baseline>0.02</baseline>
        <alwaysOn>true</alwaysOn>
        <updateRate>1.0</updateRate>
        <cameraName>kinect_ir</cameraName>
        <imageTopicName>/kinect/color/image_raw</imageTopicName>
        <cameraInfoTopicName>/kinect/color/camera_info</cameraInfoTopicName>
        <depthImageTopicName>/kinect/depth/image_raw</depthImageTopicName>
        <depthImageInfoTopicName>/kinect/depth/camera_info</depthImageInfoTopicName>
        <pointCloudTopicName>/kinect/depth/points</pointCloudTopicName>
        <frameName>kinect_optical_link</frameName>
        <pointCloudCutoff>0.5</pointCloudCutoff>
        <pointCloudCutoffMax>30.0</pointCloudCutoffMax>
        <distortionK1>0.00000001</distortionK1>
        <distortionK2>0.00000001</distortionK2>
        <distortionK3>0.00000001</distortionK3>
        <distortionT1>0.00000001</distortionT1>
        <distortionT2>0.00000001</distortionT2>
        <CxPrime>0</CxPrime>
        <Cx>0</Cx>
        <Cy>0</Cy>
        <focalLength>0</focalLength>
        <hackBaseline>0</hackBaseline>
      </plugin>
    </sensor> 
  </gazebo> -->

  <link name="imu_link">
    <inertial>
      <mass value="1e-5"/>
      <inertia ixx="1e-6" ixy="0.0" ixz="0.0" iyy="1e-6" iyz="0.0" izz="1e-6"/>
    </inertial>
  </link>

  <joint name="imu_joint" type="fixed">
    <parent link="base_link"/>
    <child link="imu_link"/>
  </joint>

  <!-- <gazebo reference="imu_link">
    <plugin name="imu_plugin" filename="libgazebo_ros_imu.so">
      <alwaysOn>true</alwaysOn>
      <bodyName>imu_link</bodyName>
      <topicName>/imu</topicName>
      <serviceName>/imu_service</serviceName>
      <update_rate>200</update_rate>
      <gaussianNoise>0.0</gaussianNoise>
    </plugin>
  </gazebo> -->

  <gazebo>
    <plugin name="imu_plugin" filename="libgazebo_ros_imu.so">
      <alwaysOn>true</alwaysOn>
      <bodyName>base_link</bodyName>
      <topicName>imu</topicName>
      <serviceName>imu_service</serviceName>
      <gaussianNoise>0.0</gaussianNoise>
      <updateRate>20.0</updateRate>
    </plugin>
  </gazebo>

  <!-- Gazebo plugin for ROS Control -->
  <gazebo>
    <plugin name="gazebo_ros_control" filename="libgazebo_ros_control.so">
      <robotNamespace>/</robotNamespace>
    </plugin>
  </gazebo>
</robot>

